Workbook

Sheet data (1)
A1: DR_Dat | B1: DR_Tim | C1: DR_NChk | D1: DR_NDoc | E1: DR_Apt | F1: DR_Kkm | G1: DR_TDoc | H1: DR_TPay | I1: DR_CDrugs | J1: DR_NDrugs | K1: DR_Suppl | L1: DR_Prod | M1: DR_Kol | N1: DR_CZak | O1: DR_CRoz | P1: DR_SDisc | Q1: TotalSum | R1: DR_CDisc | S1: DR_BCDisc | T1: DR_TabEmpl | U1: DR_VZak | V1: DR_Pos | W1: MinDate | X1: MaxDate
A2: 44774 | B2: 0.45239583 | C2: 1299 | D2: 13002561 | E2: 13 | F2: 22589 | G2: Розничная реализация | H2: 18 | I2: 26351 | J2: 911-ВЕНОЛГОН ГЕЛЬ Д/НОГ ПРИ ТЯЖЕСТИ,БОЛИ,ОТЕКАХ 100МЛ. ТУБА | K2: Протек | L2: ТВИНС ТЭК | M2: 1 | N2: 75.81 | O2: 120 | P2: 12 | Q2: =M2*O2-P2 -> 108 | R2: 9 | S2: 200010023919 | T2: 29 | U2: 1 | V2: 1
A3: 44775 | B3: 0.43678241 | C3: 1433 | D3: 13002581 | E3: 13 | F3: 22589 | G3: Розничная реализация | H3: 15 | I3: 78687 | J3: 911-ГЕЛЬ-БАЛЬЗАМ Д/НОГ КОНСКИЙ КАШТАН 100МЛ. ТУБА | K3: Катрен г.Химки | L3: ПЕРИ КРИСТАЛ | M3: 1 | N3: 66.4 | O3: 105 | P3: 10 | Q3: =M3*O3-P3 -> 95 | R3: 9 | S3: 200010002062 | T3: 29 | U3: 1 | V3: 1
A4: 44776 | B4: 0.65290509 | C4: 1619 | D4: 13002595 | E4: 13 | F4: 22589 | G4: Розничная реализация | H4: 15 | I4: 117695 | J4: 911-ГЕЛЬ-БАЛЬЗАМ Д/СУСТАВОВ РАЗОГР. ОКОПНИК+МУРАВ.К-ТА 100МЛ. | K4: Здравсервис | L4: ТВИНС ТЭК | M4: 1 | N4: 77.3 | O4: 122 | P4: 12 | Q4: =M4*O4-P4 -> 110 | R4: 9 | S4: 200010001007 | T4: 29 | U4: 1 | V4: 1
A5: 44774 | B5: 0.43967593 | C5: 1291 | D5: 13002561 | E5: 13 | F5: 22589 | G5: Розничная реализация | H5: 15 | I5: 2289 | J5: L-ТИРОКСИН 100МКГ. №100 ТАБ. /БЕРЛИН ХЕМИ/ | K5: Магнит Фарма ООО | L5: Берлин-Хеми АГ/Менарини Групп (Menarini ) | M5: 1 | N5: 129.03 | O5: 153 | P5: 7 | Q5: =M5*O5-P5 -> 146 | R5: 9 | S5: 200010004067 | T5: 29 | U5: 1 | V5: 1
A6: 44778 | B6: 0.77109954 | C6: 1890 | D6: 13002616 | E6: 13 | F6: 22589 | G6: Розничная реализация | H6: 18 | I6: 75428 | J6: L-ТИРОКСИН 150МКГ. №100 ТАБ. /БЕРЛИН ХЕМИ/ | K6: Пульс | L6: BERLIN-CHEMIE | M6: 1 | N6: 148.12 | O6: 177 | P6: 0 | Q6: =M6*O6-P6 -> 177 | R6: NULL | S6: NULL | T6: 50 | U6: 1 | V6: 1
A7: 44774 | B7: 0.50565972 | C7: 1319 | D7: 13002561 | E7: 13 | F7: 22589 | G7: Розничная реализация | H7: 18 | I7: 2039 | J7: L-ТИРОКСИН 50МКГ. №50 ТАБ. /БЕРЛИН ХЕМИ/ | K7: Пульс | L7: BERLIN-CHEMIE | M7: 1 | N7: 81.39 | O7: 99 | P7: 4 | Q7: =M7*O7-P7 -> 95 | R7: 9 | S7: 200010015482 | T7: 29 | U7: 1 | V7: 1
A8: 44777 | B8: 0.7290625 | C8: 1757 | D8: 13002606 | E8: 13 | F8: 22589 | G8: Розничная реализация | H8: 15 | I8: 2039 | J8: L-ТИРОКСИН 50МКГ. №50 ТАБ. /БЕРЛИН ХЕМИ/ | K8: Пульс | L8: BERLIN-CHEMIE | M8: 1 | N8: 81.54 | O8: 100 | P8: 5 | Q8: =M8*O8-P8 -> 95 | R8: 9 | S8: 200010015162 | T8: 50 | U8: 1 | V8: 1
A9: 44774 | B9: 0.48202546 | C9: 1309 | D9: 13002561 | E9: 13 | F9: 22589 | G9: Розничная реализация | H9: 18 | I9: 75429 | J9: L-ТИРОКСИН 75МКГ. №100 ТАБ. /БЕРЛИН ХЕМИ/ | K9: ГРАНД КАПИТАЛ СМОЛЕНСК ООО ФК | L9: Берлин-Хеми АГ/Менарини Групп (Menarini ) | M9: 1 | N9: 122.18 | O9: 144 | P9: 7 | Q9: =M9*O9-P9 -> 137 | R9: 9 | S9: 200010002868 | T9: 29 | U9: 1 | V9: 1
A10: 44774 | B10: 0.48202546 | C10: 1309 | D10: 13002561 | E10: 13 | F10: 22589 | G10: Розничная реализация | H10: 18 | I10: 75429 | J10: L-ТИРОКСИН 75МКГ. №100 ТАБ. /БЕРЛИН ХЕМИ/ | K10: ГРАНД КАПИТАЛ СМОЛЕНСК ООО ФК | L10: Берлин-Хеми АГ/Менарини Групп (Menarini ) | M10: 1 | N10: 122.18 | O10: 144 | P10: 7 | Q10: =M10*O10-P10 -> 137 | R10: 9 | S10: 200010002868 | T10: 29 | U10: 1 | V10: 2
A11: 44777 | B11: 0.7290625 | C11: 1757 | D11: 13002606 | E11: 13 | F11: 22589 | G11: Розничная реализация | H11: 15 | I11: 75429 | J11: L-ТИРОКСИН 75МКГ. №100 ТАБ. /БЕРЛИН ХЕМИ/ | K11: ГРАНД КАПИТАЛ СМОЛЕНСК ООО ФК | L11: Берлин-Хеми АГ/Менарини Групп (Menarini ) | M11: 1 | N11: 122.18 | O11: 144 | P11: 7 | Q11: =M11*O11-P11 -> 137 | R11: 9 | S11: 200010015162 | T11: 50 | U11: 1 | V11: 2
A12: 44774 | B12: 0.38320602 | C12: 1278 | D12: 13002561 | E12: 13 | F12: 22589 | G12: Розничная реализация | H12: 15 | I12: 608487 | J12: NF ВАТА ХИРУРГ. СТЕР. 100Г. /НЬЮФАРМ/ | K12: Фармкомплект ООО | L12: НьюФарм | M12: 1 | N12: 43.29 | O12: 71 | P12: 7 | Q12: =M12*O12-P12 -> 64 | R12: 9 | S12: 200010001758 | T12: 29 | U12: 1 | V12: 1
A13: 44776 | B13: 0.47851852 | C13: 1567 | D13: 13002595 | E13: 13 | F13: 22589 | G13: Розничная реализация | H13: 18 | I13: 11487 | J13: АДЖИСЕПТ МЕД+ЛИМОН №24 ТАБ. Д/РАСС. | K13: Здравсервис | L13: Аджио Фармацевтикалз Лтд (AGIO ) | M13: 1 | N13: 155.28 | O13: 213 | P13: 0 | Q13: =M13*O13-P13 -> 213 | R13: NULL | S13: NULL | T13: 29 | U13: 1 | V13: 1
A14: 44775 | B14: 0.41244213 | C14: 1429 | D14: 13002581 | E14: 13 | F14: 22589 | G14: Розничная реализация | H14: 15 | I14: 11488 | J14: АДЖИСЕПТ МЕНТОЛ+ЭВКАЛИПТ №24 ТАБ. Д/РАСС. | K14: Здравсервис | L14: Аджио Фармацевтикалз Лтд (AGIO ) | M14: 1 | N14: 157.48 | O14: 216 | P14: 15 | Q14: =M14*O14-P14 -> 201 | R14: 9 | S14: 200010001074 | T14: 29 | U14: 1 | V14: 1
A15: 44776 | B15: 0.65290509 | C15: 1619 | D15: 13002595 | E15: 13 | F15: 22589 | G15: Розничная реализация | H15: 15 | I15: 338371 | J15: АЕВИТ 200МГ. №20 КАПС. (БАД) /МЕЛИГЕН/ | K15: Пульс | L15: МЕЛИГЕН | M15: 1 | N15: 29.75 | O15: 49 | P15: 4 | Q15: =M15*O15-P15 -> 45 | R15: 9 | S15: 200010001007 | T15: 29 | U15: 1 | V15: 2
A16: 44774 | B16: 0.43633102 | C16: 1289 | D16: 13002561 | E16: 13 | F16: 22589 | G16: Розничная реализация | H16: 15 | I16: 143150 | J16: АЗАРГА 10МГ/МЛ.+5МГ/МЛ. 5МЛ. №1 ГЛ.КАПЛИ ФЛ./КАП. | K16: ВИТТА КОМПАНИ ООО | L16: АЛКОН Куврер н.в. (ALCON ) | M16: 1 | N16: 1042.25 | O16: 1314 | P16: 91 | Q16: =M16*O16-P16 -> 1223 | R16: 9 | S16: 200010000065 | T16: 29 | U16: 1 | V16: 1
A17: 44775 | B17: 0.62216435 | C17: 1484 | D17: 13002581 | E17: 13 | F17: 22589 | G17: Розничная реализация | H17: 15 | I17: 143150 | J17: АЗАРГА 10МГ/МЛ.+5МГ/МЛ. 5МЛ. №1 ГЛ.КАПЛИ ФЛ./КАП. | K17: ВИТТА КОМПАНИ ООО | L17: АЛКОН Куврер н.в. (ALCON ) | M17: 1 | N17: 1042.25 | O17: 1314 | P17: 91 | Q17: =M17*O17-P17 -> 1223 | R17: 9 | S17: 200010026887 | T17: 29 | U17: 1 | V17: 1
A18: 44776 | B18: 0.58226852 | C18: 1606 | D18: 13002595 | E18: 13 | F18: 22589 | G18: Розничная реализация | H18: 18 | I18: 343815 | J18: АЗИТРОМИЦИН 500МГ. №3 КАПС. /ПРОИЗВОДСТВО МЕДИКАМЕНТОВ/ ПроМед/ | K18: Арал плюс | L18: ПРОИЗВОДСТВО МЕДИКАМЕНТОВ ООО | M18: 1 | N18: 65.2 | O18: 84 | P18: 4 | Q18: =M18*O18-P18 -> 80 | R18: 9 | S18: 200010020729 | T18: 29 | U18: 1 | V18: 1
A19: 44776 | B19: 0.58226852 | C19: 1606 | D19: 13002595 | E19: 13 | F19: 22589 | G19: Розничная реализация | H19: 18 | I19: 343815 | J19: АЗИТРОМИЦИН 500МГ. №3 КАПС. /ПРОИЗВОДСТВО МЕДИКАМЕНТОВ/ ПроМед/ | K19: Арал плюс | L19: ПРОИЗВОДСТВО МЕДИКАМЕНТОВ ООО | M19: 1 | N19: 65.2 | O19: 84 | P19: 4 | Q19: =M19*O19-P19 -> 80 | R19: 9 | S19: 200010020729 | T19: 29 | U19: 1 | V19: 2
A20: 44776 | B20: 0.76508102 | C20: 1644 | D20: 13002595 | E20: 13 | F20: 22589 | G20: Розничная реализация | H20: 18 | I20: 342176 | J20: АЙДИ ПРОТЕКТ ПЕЛЕНКИ ОДНОР. ВПИТ. 60Х90 №10 [ID] | K20: Катрен г.Химки | L20: ОНТЕКС | M20: 1 | N20: 228.16 | O20: 347 | P20: 0 | Q20: =M20*O20-P20 -> 347 | R20: NULL | S20: NULL | T20: 29 | U20: 1 | V20: 1
A21: 44777 | B21: 0.54795139 | C21: 1714 | D21: 13002606 | E21: 13 | F21: 22589 | G21: Розничная реализация | H21: 18 | I21: 266253 | J21: АКВА МАРИС НОРМ ИНТЕНСИВ. ПРОМЫВАНИЕ 150МЛ. НАЗАЛ.СПРЕЙ | K21: ГК Надежда Фарм | L21: JADRAN (ЯДРАН) | M21: 1 | N21: 398.77 | O21: 587 | P21: 58 | Q21: =M21*O21-P21 -> 529 | R21: 9 | S21: 200010018671 | T21: 50 | U21: 1 | V21: 1
A22: 44778 | B22: 0.50699074 | C22: 1831 | D22: 13002616 | E22: 13 | F22: 22589 | G22: Розничная реализация | H22: 18 | I22: 298348 | J22: АКВА ЭЙР МОРЕ 50МЛ. НАЗАЛ.СПРЕЙ ФЛ. | K22: Фармкомплект ООО | L22: Самарамедпром ОАО | M22: 1 | N22: 56.25 | O22: 89 | P22: 8 | Q22: =M22*O22-P22 -> 81 | R22: 941 | S22: 200000000044 | T22: 50 | U22: 1 | V22: 1
A23: 44778 | B23: 0.72987269 | C23: 1882 | D23: 13002616 | E23: 13 | F23: 22589 | G23: Розничная реализация | H23: 15 | I23: 16009 | J23: АКВАДЕТРИМ 15000МЕ/МЛ. 10МЛ. КАПЛИ Д/ПРИЕМА ВНУТРЬ ФЛ./КАП. (ВИТАМИН Д3 ВОДН.Р-Р) /МЕДАНА/ | K23: Протек | L23: MEDANA PHARMA (МЕДАНА ) | M23: 1 | N23: 162.15 | O23: 195 | P23: 0 | Q23: =M23*O23-P23 -> 195 | R23: NULL | S23: NULL | T23: 50 | U23: 1 | V23: 1
A24: 44775 | B24: 0.49800926 | C24: 1454 | D24: 13002581 | E24: 13 | F24: 22589 | G24: Розничная реализация | H24: 15 | I24: 498715 | J24: АКВАЛОР ЭКСТРА ФОРТЕ 150МЛ. АЛОЭ+РОМАШКА НАЗАЛ.СПРЕЙ | K24: Пульс | L24: НИЖФАРМ | M24: 1 | N24: 454.23 | O24: 668 | P24: 66 | Q24: =M24*O24-P24 -> 602 | R24: 9 | S24: 200010000733 | T24: 29 | U24: 1 | V24: 1
A25: 44776 | B25: 0.65193287 | C25: 1618 | D25: 13002595 | E25: 13 | F25: 22589 | G25: Розничная реализация | H25: 18 | I25: 297896 | J25: АККУ-ЧЕК ТЕСТ-ПОЛОСКИ ПЕРФОРМА №100 (50Х2) [ACCU-CHEK] | K25: ГРАНД КАПИТАЛ СМОЛЕНСК ООО ФК | L25: РОШ ДИАБЕТС КЕА ГМБХ | M25: 0.5 | N25: 2550.1 | O25: 3061 | P25: 152.5 | Q25: =M25*O25-P25 -> 1378 | R25: 9 | S25: 200010004049 | T25: 29 | U25: 1 | V25: 1
A26: 44775 | B26: 0.38952546 | C26: 1427 | D26: 13002581 | E26: 13 | F26: 22589 | G26: Розничная реализация | H26: 15 | I26: 176133 | J26: АКРИДЕРМ 0,05% 30Г. №1 КРЕМ Д/НАРУЖ.ПРИМ. ТУБА /АКРИХИН/ | K26: Пульс | L26: Акрихин ХФК ОАО | M26: 1 | N26: 128.32 | O26: 156 | P26: 7 | Q26: =M26*O26-P26 -> 149 | R26: 9 | S26: 200010021998 | T26: 29 | U26: 1 | V26: 1
A27: 44776 | B27: 0.65193287 | C27: 1618 | D27: 13002595 | E27: 13 | F27: 22589 | G27: Розничная реализация | H27: 18 | I27: 176132 | J27: АКРИДЕРМ 0,05% 30Г. №1 МАЗЬ Д/НАРУЖ.ПРИМ. ТУБА /АКРИХИН/ | K27: Пульс | L27: Акрихин ХФК ОАО | M27: 1 | N27: 105.59 | O27: 128 | P27: 6 | Q27: =M27*O27-P27 -> 122 | R27: 9 | S27: 200010004049 | T27: 29 | U27: 1 | V27: 2
A28: 44778 | B28: 0.34400463 | C28: 1785 | D28: 13002616 | E28: 13 | F28: 22589 | G28: Розничная реализация | H28: 15 | I28: 305271 | J28: АКРИДЕРМ ГК 0,05%+0,1%+1% 30Г. №1 КРЕМ Д/НАРУЖ.ПРИМ. ТУБА /АКРИХИН/ | K28: Пульс | L28: Акрихин ХФК ОАО | M28: 1 | N28: 893.49 | O28: 1153 | P28: 172 | Q28: =M28*O28-P28 -> 981 | R28: 27 | S28: 200010000015 | T28: 50 | U28: 1 | V28: 1
A29: 44778 | B29: 0.63206019 | C29: 1862 | D29: 13002616 | E29: 13 | F29: 22589 | G29: Розничная реализация | H29: 18 | I29: 84612 | J29: АКТОВЕГИН 40МГ/МЛ. 2МЛ. №25 Р-Р Д/ИН. АМП. | K29: Фармкомплект ООО | L29: TAKEDA CHEMICAL IND. LTD | M29: 0.2 | N29: 1470.75 | O29: 1839 | P29: 54.8 | Q29: =M29*O29-P29 -> 313 | R29: 27 | S29: 200010000015 | T29: 50 | U29: 1 | V29: 1
A30: 44777 | B30: 0.48834491 | C30: 1685 | D30: 13002606 | E30: 13 | F30: 22589 | G30: Розничная реализация | H30: 18 | I30: 69536 | J30: АКТОВЕГИН 40МГ/МЛ. 5МЛ. №5 Р-Р Д/ИН. АМП. | K30: Протек | L30: ТАКЕДА ФАРМАСЬЮТИКАЛ КОМПАНИ ЛИМИТЕД | M30: 1 | N30: 566.81 | O30: 652 | P30: 45 | Q30: =M30*O30-P30 -> 607 | R30: 9 | S30: 200010022986 | T30: 50 | U30: 1 | V30: 1
A31: 44776 | B31: 0.63903935 | C31: 1617 | D31: 13002595 | E31: 13 | F31: 22589 | G31: Розничная реализация | H31: 15 | I31: 438876 | J31: АКУЛИЙ ЖИР ГЕЛЬ-БАЛЬЗАМ Д/ТЕЛА ОКОПНИК+САБЕЛЬНИК 125МЛ. | K31: Катрен г.Химки | L31: КОРОЛЕВФАРМ ООО | M31: 1 | N31: 92.3 | O31: 145 | P31: 14 | Q31: =M31*O31-P31 -> 131 | R31: 9 | S31: 200010001084 | T31: 29 | U31: 1 | V31: 1
A32: 44776 | B32: 0.73439815 | C32: 1636 | D32: 13002595 | E32: 13 | F32: 22589 | G32: Розничная реализация | H32: 15 | I32: 110499 | J32: АЛЕРАНА ВИТАМИННО-МИНЕРАЛЬНЫЙ КОМПЛЕКС ДЕНЬ-НОЧЬ №60 ТАБ. [ALERANA] | K32: Пульс | L32: ВЕРТЕКС | M32: 1 | N32: 694.8 | O32: 987 | P32: 0 | Q32: =M32*O32-P32 -> 987 | R32: NULL | S32: NULL | T32: 29 | U32: 1 | V32: 1
A33: 44775 | B33: 0.49315972 | C33: 1450 | D33: 13002581 | E33: 13 | F33: 22589 | G33: Розничная реализация | H33: 15 | I33: 4189 | J33: АЛЛАПИНИН 25МГ. №30 ТАБ. /ВИЛАР/ | K33: Здравсервис | L33: ВИЛАР ФАРМЦЕНТР ЗАО | M33: 1 | N33: 559.91 | O33: 624 | P33: 18 | Q33: =M33*O33-P33 -> 606 | R33: 9 | S33: 200010019550 | T33: 29 | U33: 1 | V33: 1
A34: 44776 | B34: 0.77318287 | C34: 1645 | D34: 13002595 | E34: 13 | F34: 22589 | G34: Розничная реализация | H34: 18 | I34: 348072 | J34: АЛЛЕРВЭЙ 5МГ. №10 ТАБ. П/О | K34: Катрен г.Химки | L34: Д-р Редди с Лабораторис Лтд / Dr.REDDY's | M34: 1 | N34: 227.13 | O34: 307 | P34: 0 | Q34: =M34*O34-P34 -> 307 | R34: NULL | S34: NULL | T34: 29 | U34: 1 | V34: 1
A35: 44775 | B35: 0.37314815 | C35: 1420 | D35: 13002581 | E35: 13 | F35: 22589 | G35: Розничная реализация | H35: 15 | I35: 342266 | J35: АЛЛОХОЛ №50 ТАБ. П/О /ФАРМСТАНДАРТ/ | K35: Катрен г.Химки | L35: Фармстандарт-Томскхимфарм,ОАО | M35: 1 | N35: 52.91 | O35: 76 | P35: 5 | Q35: =M35*O35-P35 -> 71 | R35: 9 | S35: 200010011822 | T35: 29 | U35: 1 | V35: 1
A36: 44775 | B36: 0.46716435 | C36: 1441 | D36: 13002581 | E36: 13 | F36: 22589 | G36: Розничная реализация | H36: 18 | I36: 83 | J36: АЛМАГЕЛЬ А 170МЛ. №1 СУСП. Д/ПРИЕМА ВНУТРЬ ФЛ. /БАЛКАН ФАРМА-ТРОЯН/ | K36: Катрен г.Химки | L36: Балканфарма - Троян АД | M36: 1 | N36: 308.9 | O36: 371 | P36: 25 | Q36: =M36*O36-P36 -> 346 | R36: 9 | S36: 200010022273 | T36: 29 | U36: 1 | V36: 1
A37: 44778 | B37: 0.76708333 | C37: 1888 | D37: 13002616 | E37: 13 | F37: 22589 | G37: Розничная реализация | H37: 18 | I37: 60823 | J37: АЛЬФА НОРМИКС 200МГ. №12 ТАБ. П/П/О | K37: Катрен г.Химки | L37: АЛЬФАСИГМА С.П.А. | M37: 1 | N37: 864.03 | O37: 1115 | P37: 78 | Q37: =M37*O37-P37 -> 1037 | R37: 9 | S37: 200010004411 | T37: 50 | U37: 1 | V37: 1
A38: 44775 | B38: 0.75609954 | C38: 1522 | D38: 13002581 | E38: 13 | F38: 22589 | G38: Розничная реализация | H38: 18 | I38: 321882 | J38: АЛЬФА НОРМИКС 200МГ. №28 ТАБ. П/П/О | K38: ЕАПТЕКА ООО | L38: Альфа-Вассерман С.п.А. ALFA | M38: 1 | N38: 1629.21 | O38: 1706 | P38: 0 | Q38: =M38*O38-P38 -> 1706 | R38: NULL | S38: NULL | T38: 29 | U38: 2 | V38: 1
A39: 44777 | B39: 0.52769676 | C39: 1704 | D39: 13002606 | E39: 13 | F39: 22589 | G39: Розничная реализация | H39: 15 | I39: 466557 | J39: АЛЬФА ТОКОФЕРОЛА АЦЕТАТ 200МГ. №30 КАПС. (ВИТАМИН Е) /МИНСКИНТЕРКАПС/ | K39: Протек | L39: МИНСКИНТЕРКАПС | M39: 1 | N39: 100.58 | O39: 146 | P39: 36 | Q39: =M39*O39-P39 -> 110 | R39: 939 | S39: 200000000042 | T39: 50 | U39: 1 | V39: 1
A40: 44775 | B40: 0.62216435 | C40: 1484 | D40: 13002581 | E40: 13 | F40: 22589 | G40: Розничная реализация | H40: 15 | I40: 152071 | J40: АЛЬФАГАН Р 0,15% 5МЛ. ГЛ.КАПЛИ ФЛ./КАП. | K40: Катрен г.Химки | L40: АЛЛЕРГАН ФАРМАСЬЮТИКЭЛЗ АЙРЛЭНД | M40: 1 | N40: 724.22 | O40: 935 | P40: 65 | Q40: =M40*O40-P40 -> 870 | R40: 9 | S40: 200010026887 | T40: 29 | U40: 1 | V40: 2
...

Sheet сводная
A3: Названия строк | B3: Сумма по столбцу DR_Kol | C3: Сумма по столбцу TotalSum | D3: Число разных элементов в столбце DR_Dat
A4: 911-ВЕНОЛГОН ГЕЛЬ Д/НОГ ПРИ ТЯЖЕСТИ,БОЛИ,ОТЕКАХ 100МЛ. ТУБА | B4: 1 | C4: 108 | D4: 1
A5: 911-ГЕЛЬ-БАЛЬЗАМ Д/НОГ КОНСКИЙ КАШТАН 100МЛ. ТУБА | B5: 1 | C5: 95 | D5: 1
A6: 911-ГЕЛЬ-БАЛЬЗАМ Д/СУСТАВОВ РАЗОГР. ОКОПНИК+МУРАВ.К-ТА 100МЛ. | B6: 1 | C6: 110 | D6: 1
A7: L-ТИРОКСИН 100МКГ. №100 ТАБ. /БЕРЛИН ХЕМИ/ | B7: 1 | C7: 146 | D7: 1
A8: L-ТИРОКСИН 150МКГ. №100 ТАБ. /БЕРЛИН ХЕМИ/ | B8: 1 | C8: 177 | D8: 1
A9: L-ТИРОКСИН 50МКГ. №50 ТАБ. /БЕРЛИН ХЕМИ/ | B9: 2 | C9: 190 | D9: 2
A10: L-ТИРОКСИН 75МКГ. №100 ТАБ. /БЕРЛИН ХЕМИ/ | B10: 3 | C10: 411 | D10: 2
A11: NF ВАТА ХИРУРГ. СТЕР. 100Г. /НЬЮФАРМ/ | B11: 1 | C11: 64 | D11: 1
A12: АДЖИСЕПТ МЕД+ЛИМОН №24 ТАБ. Д/РАСС. | B12: 1 | C12: 213 | D12: 1
A13: АДЖИСЕПТ МЕНТОЛ+ЭВКАЛИПТ №24 ТАБ. Д/РАСС. | B13: 1 | C13: 201 | D13: 1
A14: АЕВИТ 200МГ. №20 КАПС. (БАД) /МЕЛИГЕН/ | B14: 1 | C14: 45 | D14: 1
A15: АЗАРГА 10МГ/МЛ.+5МГ/МЛ. 5МЛ. №1 ГЛ.КАПЛИ ФЛ./КАП. | B15: 2 | C15: 2446 | D15: 2
... A807: Общий итог | B807: 1608.861 | C807: 349767.88 | D807: 5

Sheet расчеты
A1: Name | B1: Count | C1: Perc_Count | D1: CumSumCount | E1: ABC_Count | F1: TotalSum | G1: Perc_Tsum | H1: CumSumTSUM | I1: ABC_TotalSum | J1: Period | K1: MonthlyTurnover | L1: Perc_MTurnover | M1: CumSum_MTurnover | N1: ABC_MonthlyTurnover | O1: ABC | P1: var | Q1: XYZ | R1: ABCXYZ
A2: 911-ВЕНОЛГОН ГЕЛЬ Д/НОГ ПРИ ТЯЖЕСТИ,БОЛИ,ОТЕКАХ 100МЛ. ТУБА | B2: 1 | C2: 0.00062155775 | D2: 0.68576467 | E2: A | F2: 108 | G2: 0.00030877621 | H2: 0.96249751 | I2: C | J2: 5 | K2: 6 | L2: 0.00062155775 | M2: 0.68576467 | N2: A | O2: ACA | P2: =VLOOKUP(A2,вариация!A$2:G$805,2,FALSE) -> 2.236068 | Q2: =IF(вариация!H3="Yes",IF(P5<0.1,"X",IF(P5<0.25,"Y","Z")),"") | R2: =O2&Q2 -> ACA
A3: 911-ГЕЛЬ-БАЛЬЗАМ Д/НОГ КОНСКИЙ КАШТАН 100МЛ. ТУБА | B3: 1 | C3: 0.00062155775 | D3: 0.68638623 | E3: A | F3: 95 | G3: 0.0002716087 | H3: 0.97256933 | I3: C | J3: 5 | K3: 6 | L3: 0.00062155775 | M3: 0.68638623 | N3: A | O3: ACA | P3: =VLOOKUP(A3,вариация!A$2:G$805,2,FALSE) -> 2.236068 | Q3: =IF(вариация!H4="Yes",IF(P6<0.1,"X",IF(P6<0.25,"Y","Z")),"") | R3: =O3&Q3 -> ACA
A4: 911-ГЕЛЬ-БАЛЬЗАМ Д/СУСТАВОВ РАЗОГР. ОКОПНИК+МУРАВ.К-ТА 100МЛ. | B4: 1 | C4: 0.00062155775 | D4: 0.68700779 | E4: A | F4: 110 | G4: 0.00031449429 | H4: 0.96062127 | I4: C | J4: 5 | K4: 6 | L4: 0.00062155775 | M4: 0.68700779 | N4: A | O4: ACA | P4: =VLOOKUP(A4,вариация!A$2:G$805,2,FALSE) -> 2.236068 | Q4: =IF(вариация!H5="Yes",IF(P7<0.1,"X",IF(P7<0.25,"Y","Z")),"") | R4: =O4&Q4 -> ACA
A5: L-ТИРОКСИН 100МКГ. №100 ТАБ. /БЕРЛИН ХЕМИ/ | B5: 1 | C5: 0.00062155775 | D5: 0.68762934 | E5: A | F5: 146 | G5: 0.00041741969 | H5: 0.9369741 | I5: B | J5: 5 | K5: 6 | L5: 0.00062155775 | M5: 0.68762934 | N5: A | O5: ABA | P5: =VLOOKUP(A5,вариация!A$2:G$805,2,FALSE) -> 2.236068 | Q5: =IF(вариация!H6="Yes",IF(P8<0.1,"X",IF(P8<0.25,"Y","Z")),"") | R5: =O5&Q5 -> ABA
A6: L-ТИРОКСИН 150МКГ. №100 ТАБ. /БЕРЛИН ХЕМИ/ | B6: 1 | C6: 0.00062155775 | D6: 0.6882509 | E6: A | F6: 177 | G6: 0.0005060499 | H6: 0.91604282 | I6: B | J6: 5 | K6: 6 | L6: 0.00062155775 | M6: 0.6882509 | N6: A | O6: ABA | P6: =VLOOKUP(A6,вариация!A$2:G$805,2,FALSE) -> 2.236068 | Q6: =IF(вариация!H7="Yes",IF(P9<0.1,"X",IF(P9<0.25,"Y","Z")),"") | R6: =O6&Q6 -> ABA
A7: L-ТИРОКСИН 50МКГ. №50 ТАБ. /БЕРЛИН ХЕМИ/ | B7: 2 | C7: 0.0012431155 | D7: 0.52148696 | E7: A | F7: 190 | G7: 0.00054321741 | H7: 0.91125964 | I7: B | J7: 5 | K7: 12 | L7: 0.0012431155 | M7: 0.52148696 | N7: A | O7: ABA | P7: =VLOOKUP(A7,вариация!A$2:G$805,2,FALSE) -> 1.3693064 | Q7: =IF(вариация!H8="Yes",IF(P10<0.1,"X",IF(P10<0.25,"Y","Z")),"") | R7: =O7&Q7 -> ABA
A8: L-ТИРОКСИН 75МКГ. №100 ТАБ. /БЕРЛИН ХЕМИ/ | B8: 3 | C8: 0.0018646733 | D8: 0.41395746 | E8: A | F8: 411 | G8: 0.001175065 | H8: 0.72322364 | I8: A | J8: 5 | K8: 18 | L8: 0.0018646733 | M8: 0.41395746 | N8: A | O8: AAA | P8: =VLOOKUP(A8,вариация!A$2:G$805,2,FALSE) -> 1.490712 | Q8: =IF(вариация!H9="Yes",IF(P11<0.1,"X",IF(P11<0.25,"Y","Z")),"") | R8: =O8&Q8 -> AAA
A9: NF ВАТА ХИРУРГ. СТЕР. 100Г. /НЬЮФАРМ/ | B9: 1 | C9: 0.00062155775 | D9: 0.68887246 | E9: A | F9: 64 | G9: 0.0001829785 | H9: 0.98992261 | I9: C | J9: 5 | K9: 6 | L9: 0.00062155775 | M9: 0.68887246 | N9: A | O9: ACA | P9: =VLOOKUP(A9,вариация!A$2:G$805,2,FALSE) -> 2.236068 | Q9: =IF(вариация!H10="Yes",IF(P12<0.1,"X",IF(P12<0.25,"Y","Z")),"") | R9: =O9&Q9 -> ACA
A10: АДЖИСЕПТ МЕД+ЛИМОН №24 ТАБ. Д/РАСС. | B10: 1 | C10: 0.00062155775 | D10: 0.68949402 | E10: A | F10: 213 | G10: 0.00060897531 | H10: 0.8968657 | I10: B | J10: 5 | K10: 6 | L10: 0.00062155775 | M10: 0.68949402 | N10: A | O10: ABA | P10: =VLOOKUP(A10,вариация!A$2:G$805,2,FALSE) -> 2.236068 | Q10: =IF(вариация!H11="Yes",IF(P13<0.1,"X",IF(P13<0.25,"Y","Z")),"") | R10: =O10&Q10 -> ABA
A11: АДЖИСЕПТ МЕНТОЛ+ЭВКАЛИПТ №24 ТАБ. Д/РАСС. | B11: 1 | C11: 0.00062155775 | D11: 0.69011557 | E11: A | F11: 201 | G11: 0.00057466684 | H11: 0.90511402 | I11: B | J11: 5 | K11: 6 | L11: 0.00062155775 | M11: 0.69011557 | N11: A | O11: ABA | P11: =VLOOKUP(A11,вариация!A$2:G$805,2,FALSE) -> 2.236068 | Q11: =IF(вариация!H12="Yes",IF(P14<0.1,"X",IF(P14<0.25,"Y","Z")),"") | R11: =O11&Q11 -> ABA
A12: АЕВИТ 200МГ. №20 КАПС. (БАД) /МЕЛИГЕН/ | B12: 1 | C12: 0.00062155775 | D12: 0.69073713 | E12: A | F12: 45 | G12: 0.00012865675 | H12: 0.99562618 | I12: C | J12: 5 | K12: 6 | L12: 0.00062155775 | M12: 0.69073713 | N12: A | O12: ACA | P12: =VLOOKUP(A12,вариация!A$2:G$805,2,FALSE) -> 2.236068 | Q12: =IF(вариация!H13="Yes",IF(P15<0.1,"X",IF(P15<0.25,"Y","Z")),"") | R12: =O12&Q12 -> ACA
A13: АЗАРГА 10МГ/МЛ.+5МГ/МЛ. 5МЛ. №1 ГЛ.КАПЛИ ФЛ./КАП. | B13: 2 | C13: 0.0012431155 | D13: 0.52273007 | E13: A | F13: 2446 | G13: 0.0069932094 | H13: 0.13641588 | I13: A | J13: 5 | K13: 12 | L13: 0.0012431155 | M13: 0.52273007 | N13: A | O13: AAA | P13: =VLOOKUP(A13,вариация!A$2:G$805,2,FALSE) -> 1.3693064 | Q13: =IF(вариация!H14="Yes",IF(P16<0.1,"X",IF(P16<0.25,"Y","Z")),"") | R13: =O13&Q13 -> AAA
... A804: ЮНИДОКС СОЛЮТАБ 100МГ. №20 ТАБ.ДИСПЕРГ. /АСТЕЛЛАС/ | B804: 1 | C804: 0.00062155775 | D804: 0.99343576 | E804: C | F804: 639 | G804: 0.0018269259 | H804: 0.55864988 | I804: A | J804: 5 | K804: 6 | L804: 0.00062155775 | M804: 0.99343576 | N804: C | O804: CAC | P804: =VLOOKUP(A804,вариация!A$2:G$805,2,FALSE) -> 2.236068 | Q804: =IF(вариация!H805="Yes",IF(P807<0.1,"X",IF(P807<0.25,"Y","Z")),"") | R804: =O804&Q804 -> CAC

Sheet вариация
A2: Name | B2: var_koef | C2: 44774 | D2: =C2+1 -> 44775 | E2: =D2+1 -> 44776 | F2: =E2+1 -> 44777 | G2: =F2+1 -> 44778 | H2: minDaysCheck
A3: 911-ВЕНОЛГОН ГЕЛЬ Д/НОГ ПРИ ТЯЖЕСТИ,БОЛИ,ОТЕКАХ 100МЛ. ТУБА | B3: =_xlfn.STDEV.S(C3:G3)/AVERAGE(C3:G3) -> 2.236068 | C3: =SUMIFS('data (1)'!$M:$M,'data (1)'!$J:$J,"="&$A3,'data (1)'!$A:$A,"="&вариация!C$2) -> 1 | D3: =SUMIFS('data (1)'!$M:$M,'data (1)'!$J:$J,"="&$A3,'data (1)'!$A:$A,"="&вариация!D$2) -> 0 | E3: =SUMIFS('data (1)'!$M:$M,'data (1)'!$J:$J,"="&$A3,'data (1)'!$A:$A,"="&вариация!E$2) -> 0 | F3: =SUMIFS('data (1)'!$M:$M,'data (1)'!$J:$J,"="&$A3,'data (1)'!$A:$A,"="&вариация!F$2) -> 0 | G3: =SUMIFS('data (1)'!$M:$M,'data (1)'!$J:$J,"="&$A3,'data (1)'!$A:$A,"="&вариация!G$2) -> 0 | H3: =IF(COUNTIF(C3:G3,">0") >=3, "Yes", "No") -> No
A4: 911-ГЕЛЬ-БАЛЬЗАМ Д/НОГ КОНСКИЙ КАШТАН 100МЛ. ТУБА | B4: =_xlfn.STDEV.S(C4:G4)/AVERAGE(C4:G4) -> 2.236068 | C4: =SUMIFS('data (1)'!$M:$M,'data (1)'!$J:$J,"="&$A4,'data (1)'!$A:$A,"="&вариация!C$2) -> 0 | D4: =SUMIFS('data (1)'!$M:$M,'data (1)'!$J:$J,"="&$A4,'data (1)'!$A:$A,"="&вариация!D$2) -> 1 | E4: =SUMIFS('data (1)'!$M:$M,'data (1)'!$J:$J,"="&$A4,'data (1)'!$A:$A,"="&вариация!E$2) -> 0 | F4: =SUMIFS('data (1)'!$M:$M,'data (1)'!$J:$J,"="&$A4,'data (1)'!$A:$A,"="&вариация!F$2) -> 0 | G4: =SUMIFS('data (1)'!$M:$M,'data (1)'!$J:$J,"="&$A4,'data (1)'!$A:$A,"="&вариация!G$2) -> 0 | H4: =IF(COUNTIF(C4:G4,">0") >=3, "Yes", "No") -> No
A5: 911-ГЕЛЬ-БАЛЬЗАМ Д/СУСТАВОВ РАЗОГР. ОКОПНИК+МУРАВ.К-ТА 100МЛ. | B5: =_xlfn.STDEV.S(C5:G5)/AVERAGE(C5:G5) -> 2.236068 | C5: =SUMIFS('data (1)'!$M:$M,'data (1)'!$J:$J,"="&$A5,'data (1)'!$A:$A,"="&вариация!C$2) -> 0 | D5: =SUMIFS('data (1)'!$M:$M,'data (1)'!$J:$J,"="&$A5,'data (1)'!$A:$A,"="&вариация!D$2) -> 0 | E5: =SUMIFS('data (1)'!$M:$M,'data (1)'!$J:$J,"="&$A5,'data (1)'!$A:$A,"="&вариация!E$2) -> 1 | F5: =SUMIFS('data (1)'!$M:$M,'data (1)'!$J:$J,"="&$A5,'data (1)'!$A:$A,"="&вариация!F$2) -> 0 | G5: =SUMIFS('data (1)'!$M:$M,'data (1)'!$J:$J,"="&$A5,'data (1)'!$A:$A,"="&вариация!G$2) -> 0 | H5: =IF(COUNTIF(C5:G5,">0") >=3, "Yes", "No") -> No
A6: L-ТИРОКСИН 100МКГ. №100 ТАБ. /БЕРЛИН ХЕМИ/ | B6: =_xlfn.STDEV.S(C6:G6)/AVERAGE(C6:G6) -> 2.236068 | C6: =SUMIFS('data (1)'!$M:$M,'data (1)'!$J:$J,"="&$A6,'data (1)'!$A:$A,"="&вариация!C$2) -> 1 | D6: =SUMIFS('data (1)'!$M:$M,'data (1)'!$J:$J,"="&$A6,'data (1)'!$A:$A,"="&вариация!D$2) -> 0 | E6: =SUMIFS('data (1)'!$M:$M,'data (1)'!$J:$J,"="&$A6,'data (1)'!$A:$A,"="&вариация!E$2) -> 0 | F6: =SUMIFS('data (1)'!$M:$M,'data (1)'!$J:$J,"="&$A6,'data (1)'!$A:$A,"="&вариация!F$2) -> 0 | G6: =SUMIFS('data (1)'!$M:$M,'data (1)'!$J:$J,"="&$A6,'data (1)'!$A:$A,"="&вариация!G$2) -> 0 | H6: =IF(COUNTIF(C6:G6,">0") >=3, "Yes", "No") -> No
A7: L-ТИРОКСИН 150МКГ. №100 ТАБ. /БЕРЛИН ХЕМИ/ | B7: =_xlfn.STDEV.S(C7:G7)/AVERAGE(C7:G7) -> 2.236068 | C7: =SUMIFS('data (1)'!$M:$M,'data (1)'!$J:$J,"="&$A7,'data (1)'!$A:$A,"="&вариация!C$2) -> 0 | D7: =SUMIFS('data (1)'!$M:$M,'data (1)'!$J:$J,"="&$A7,'data (1)'!$A:$A,"="&вариация!D$2) -> 0 | E7: =SUMIFS('data (1)'!$M:$M,'data (1)'!$J:$J,"="&$A7,'data (1)'!$A:$A,"="&вариация!E$2) -> 0 | F7: =SUMIFS('data (1)'!$M:$M,'data (1)'!$J:$J,"="&$A7,'data (1)'!$A:$A,"="&вариация!F$2) -> 0 | G7: =SUMIFS('data (1)'!$M:$M,'data (1)'!$J:$J,"="&$A7,'data (1)'!$A:$A,"="&вариация!G$2) -> 1 | H7: =IF(COUNTIF(C7:G7,">0") >=3, "Yes", "No") -> No
A8: L-ТИРОКСИН 50МКГ. №50 ТАБ. /БЕРЛИН ХЕМИ/ | B8: =_xlfn.STDEV.S(C8:G8)/AVERAGE(C8:G8) -> 1.3693064 | C8: =SUMIFS('data (1)'!$M:$M,'data (1)'!$J:$J,"="&$A8,'data (1)'!$A:$A,"="&вариация!C$2) -> 1 | D8: =SUMIFS('data (1)'!$M:$M,'data (1)'!$J:$J,"="&$A8,'data (1)'!$A:$A,"="&вариация!D$2) -> 0 | E8: =SUMIFS('data (1)'!$M:$M,'data (1)'!$J:$J,"="&$A8,'data (1)'!$A:$A,"="&вариация!E$2) -> 0 | F8: =SUMIFS('data (1)'!$M:$M,'data (1)'!$J:$J,"="&$A8,'data (1)'!$A:$A,"="&вариация!F$2) -> 1 | G8: =SUMIFS('data (1)'!$M:$M,'data (1)'!$J:$J,"="&$A8,'data (1)'!$A:$A,"="&вариация!G$2) -> 0 | H8: =IF(COUNTIF(C8:G8,">0") >=3, "Yes", "No") -> No
A9: L-ТИРОКСИН 75МКГ. №100 ТАБ. /БЕРЛИН ХЕМИ/ | B9: =_xlfn.STDEV.S(C9:G9)/AVERAGE(C9:G9) -> 1.490712 | C9: =SUMIFS('data (1)'!$M:$M,'data (1)'!$J:$J,"="&$A9,'data (1)'!$A:$A,"="&вариация!C$2) -> 2 | D9: =SUMIFS('data (1)'!$M:$M,'data (1)'!$J:$J,"="&$A9,'data (1)'!$A:$A,"="&вариация!D$2) -> 0 | E9: =SUMIFS('data (1)'!$M:$M,'data (1)'!$J:$J,"="&$A9,'data (1)'!$A:$A,"="&вариация!E$2) -> 0 | F9: =SUMIFS('data (1)'!$M:$M,'data (1)'!$J:$J,"="&$A9,'data (1)'!$A:$A,"="&вариация!F$2) -> 1 | G9: =SUMIFS('data (1)'!$M:$M,'data (1)'!$J:$J,"="&$A9,'data (1)'!$A:$A,"="&вариация!G$2) -> 0 | H9: =IF(COUNTIF(C9:G9,">0") >=3, "Yes", "No") -> No
A10: NF ВАТА ХИРУРГ. СТЕР. 100Г. /НЬЮФАРМ/ | B10: =_xlfn.STDEV.S(C10:G10)/AVERAGE(C10:G10) -> 2.236068 | C10: =SUMIFS('data (1)'!$M:$M,'data (1)'!$J:$J,"="&$A10,'data (1)'!$A:$A,"="&вариация!C$2) -> 1 | D10: =SUMIFS('data (1)'!$M:$M,'data (1)'!$J:$J,"="&$A10,'data (1)'!$A:$A,"="&вариация!D$2) -> 0 | E10: =SUMIFS('data (1)'!$M:$M,'data (1)'!$J:$J,"="&$A10,'data (1)'!$A:$A,"="&вариация!E$2) -> 0 | F10: =SUMIFS('data (1)'!$M:$M,'data (1)'!$J:$J,"="&$A10,'data (1)'!$A:$A,"="&вариация!F$2) -> 0 | G10: =SUMIFS('data (1)'!$M:$M,'data (1)'!$J:$J,"="&$A10,'data (1)'!$A:$A,"="&вариация!G$2) -> 0 | H10: =IF(COUNTIF(C10:G10,">0") >=3, "Yes", "No") -> No
A11: АДЖИСЕПТ МЕД+ЛИМОН №24 ТАБ. Д/РАСС. | B11: =_xlfn.STDEV.S(C11:G11)/AVERAGE(C11:G11) -> 2.236068 | C11: =SUMIFS('data (1)'!$M:$M,'data (1)'!$J:$J,"="&$A11,'data (1)'!$A:$A,"="&вариация!C$2) -> 0 | D11: =SUMIFS('data (1)'!$M:$M,'data (1)'!$J:$J,"="&$A11,'data (1)'!$A:$A,"="&вариация!D$2) -> 0 | E11: =SUMIFS('data (1)'!$M:$M,'data (1)'!$J:$J,"="&$A11,'data (1)'!$A:$A,"="&вариация!E$2) -> 1 | F11: =SUMIFS('data (1)'!$M:$M,'data (1)'!$J:$J,"="&$A11,'data (1)'!$A:$A,"="&вариация!F$2) -> 0 | G11: =SUMIFS('data (1)'!$M:$M,'data (1)'!$J:$J,"="&$A11,'data (1)'!$A:$A,"="&вариация!G$2) -> 0 | H11: =IF(COUNTIF(C11:G11,">0") >=3, "Yes", "No") -> No
A12: АДЖИСЕПТ МЕНТОЛ+ЭВКАЛИПТ №24 ТАБ. Д/РАСС. | B12: =_xlfn.STDEV.S(C12:G12)/AVERAGE(C12:G12) -> 2.236068 | C12: =SUMIFS('data (1)'!$M:$M,'data (1)'!$J:$J,"="&$A12,'data (1)'!$A:$A,"="&вариация!C$2) -> 0 | D12: =SUMIFS('data (1)'!$M:$M,'data (1)'!$J:$J,"="&$A12,'data (1)'!$A:$A,"="&вариация!D$2) -> 1 | E12: =SUMIFS('data (1)'!$M:$M,'data (1)'!$J:$J,"="&$A12,'data (1)'!$A:$A,"="&вариация!E$2) -> 0 | F12: =SUMIFS('data (1)'!$M:$M,'data (1)'!$J:$J,"="&$A12,'data (1)'!$A:$A,"="&вариация!F$2) -> 0 | G12: =SUMIFS('data (1)'!$M:$M,'data (1)'!$J:$J,"="&$A12,'data (1)'!$A:$A,"="&вариация!G$2) -> 0 | H12: =IF(COUNTIF(C12:G12,">0") >=3, "Yes", "No") -> No
A13: АЕВИТ 200МГ. №20 КАПС. (БАД) /МЕЛИГЕН/ | B13: =_xlfn.STDEV.S(C13:G13)/AVERAGE(C13:G13) -> 2.236068 | C13: =SUMIFS('data (1)'!$M:$M,'data (1)'!$J:$J,"="&$A13,'data (1)'!$A:$A,"="&вариация!C$2) -> 0 | D13: =SUMIFS('data (1)'!$M:$M,'data (1)'!$J:$J,"="&$A13,'data (1)'!$A:$A,"="&вариация!D$2) -> 0 | E13: =SUMIFS('data (1)'!$M:$M,'data (1)'!$J:$J,"="&$A13,'data (1)'!$A:$A,"="&вариация!E$2) -> 1 | F13: =SUMIFS('data (1)'!$M:$M,'data (1)'!$J:$J,"="&$A13,'data (1)'!$A:$A,"="&вариация!F$2) -> 0 | G13: =SUMIFS('data (1)'!$M:$M,'data (1)'!$J:$J,"="&$A13,'data (1)'!$A:$A,"="&вариация!G$2) -> 0 | H13: =IF(COUNTIF(C13:G13,">0") >=3, "Yes", "No") -> No
A14: АЗАРГА 10МГ/МЛ.+5МГ/МЛ. 5МЛ. №1 ГЛ.КАПЛИ ФЛ./КАП. | B14: =_xlfn.STDEV.S(C14:G14)/AVERAGE(C14:G14) -> 1.3693064 | C14: =SUMIFS('data (1)'!$M:$M,'data (1)'!$J:$J,"="&$A14,'data (1)'!$A:$A,"="&вариация!C$2) -> 1 | D14: =SUMIFS('data (1)'!$M:$M,'data (1)'!$J:$J,"="&$A14,'data (1)'!$A:$A,"="&вариация!D$2) -> 1 | E14: =SUMIFS('data (1)'!$M:$M,'data (1)'!$J:$J,"="&$A14,'data (1)'!$A:$A,"="&вариация!E$2) -> 0 | F14: =SUMIFS('data (1)'!$M:$M,'data (1)'!$J:$J,"="&$A14,'data (1)'!$A:$A,"="&вариация!F$2) -> 0 | G14: =SUMIFS('data (1)'!$M:$M,'data (1)'!$J:$J,"="&$A14,'data (1)'!$A:$A,"="&вариация!G$2) -> 0 | H14: =IF(COUNTIF(C14:G14,">0") >=3, "Yes", "No") -> No
... A805: ЮНИДОКС СОЛЮТАБ 100МГ. №20 ТАБ.ДИСПЕРГ. /АСТЕЛЛАС/ | B805: =_xlfn.STDEV.S(C805:G805)/AVERAGE(C805:G805) -> 2.236068 | C805: =SUMIFS('data (1)'!$M:$M,'data (1)'!$J:$J,"="&$A805,'data (1)'!$A:$A,"="&вариация!C$2) -> 0 | D805: =SUMIFS('data (1)'!$M:$M,'data (1)'!$J:$J,"="&$A805,'data (1)'!$A:$A,"="&вариация!D$2) -> 0 | E805: =SUMIFS('data (1)'!$M:$M,'data (1)'!$J:$J,"="&$A805,'data (1)'!$A:$A,"="&вариация!E$2) -> 0 | F805: =SUMIFS('data (1)'!$M:$M,'data (1)'!$J:$J,"="&$A805,'data (1)'!$A:$A,"="&вариация!F$2) -> 0 | G805: =SUMIFS('data (1)'!$M:$M,'data (1)'!$J:$J,"="&$A805,'data (1)'!$A:$A,"="&вариация!G$2) -> 1 | H805: =IF(COUNTIF(C805:G805,">0") >=3, "Yes", "No") -> No

Sheet ABC-groups
A3: Названия строк | B3: Число элементов в столбце ABC
A4: AAA | B4: 186
A5: ABA | B5: 137
A6: ACA | B6: 129
A7: BAB | B7: 102
A8: BBB | B8: 73
A9: BCB | B9: 67
A10: CAC | B10: 43
A11: CBC | B11: 29
A12: CCC | B12: 37
A13: Общий итог | B13: 803

Sheet ABCDXYZ-groups
A3: Названия строк | B3: Число элементов в столбце ABCXYZ
A4: AAA | B4: 149 | E4: Отсутствие Z - указывает, что группу по XYZ оценить невозможно, тк товар продавался меньше 2х дней из периода.
A5: AAAZ | B5: 37
A6: ABA | B6: 117
A7: ABAZ | B7: 20
A8: ACA | B8: 121
A9: ACAZ | B9: 8
A10: BAB | B10: 102
A11: BBB | B11: 73
A12: BCB | B12: 67
A13: CAC | B13: 42
A14: CACZ | B14: 1
A15: CBC | B15: 29
A16: CCC | B16: 37
A17: Общий итог | B17: 803
